[2024-07-22T12:13:42.197+0000] {local_task_job_runner.py:120} INFO - ::group::Pre task execution logs
[2024-07-22T12:13:42.214+0000] {taskinstance.py:2076} INFO - Dependencies all met for dep_context=non-requeueable deps ti=<TaskInstance: count_accidents.number_of_accidents manual__2024-07-22T12:13:40.726568+00:00 [queued]>
[2024-07-22T12:13:42.219+0000] {taskinstance.py:2076} INFO - Dependencies all met for dep_context=requeueable deps ti=<TaskInstance: count_accidents.number_of_accidents manual__2024-07-22T12:13:40.726568+00:00 [queued]>
[2024-07-22T12:13:42.219+0000] {taskinstance.py:2306} INFO - Starting attempt 1 of 1
[2024-07-22T12:13:42.225+0000] {taskinstance.py:2330} INFO - Executing <Task(BashOperator): number_of_accidents> on 2024-07-22 12:13:40.726568+00:00
[2024-07-22T12:13:42.230+0000] {warnings.py:112} WARNING - /home/airflow/.local/lib/python3.12/site-packages/airflow/task/task_runner/standard_task_runner.py:61: DeprecationWarning: This process (pid=523) is multi-threaded, use of fork() may lead to deadlocks in the child.
  pid = os.fork()

[2024-07-22T12:13:42.230+0000] {standard_task_runner.py:63} INFO - Started process 525 to run task
[2024-07-22T12:13:42.230+0000] {standard_task_runner.py:90} INFO - Running: ['airflow', 'tasks', 'run', 'count_accidents', 'number_of_accidents', 'manual__2024-07-22T12:13:40.726568+00:00', '--job-id', '1785', '--raw', '--subdir', 'DAGS_FOLDER/count_accidents.py', '--cfg-path', '/tmp/tmp5bblcro9']
[2024-07-22T12:13:42.232+0000] {standard_task_runner.py:91} INFO - Job 1785: Subtask number_of_accidents
[2024-07-22T12:13:42.288+0000] {task_command.py:426} INFO - Running <TaskInstance: count_accidents.number_of_accidents manual__2024-07-22T12:13:40.726568+00:00 [running]> on host 0deccaecadd1
[2024-07-22T12:13:42.362+0000] {taskinstance.py:2648} INFO - Exporting env vars: AIRFLOW_CTX_DAG_OWNER='airflow' AIRFLOW_CTX_DAG_ID='count_accidents' AIRFLOW_CTX_TASK_ID='number_of_accidents' AIRFLOW_CTX_EXECUTION_DATE='2024-07-22T12:13:40.726568+00:00' AIRFLOW_CTX_TRY_NUMBER='1' AIRFLOW_CTX_DAG_RUN_ID='manual__2024-07-22T12:13:40.726568+00:00'
[2024-07-22T12:13:42.363+0000] {taskinstance.py:430} INFO - ::endgroup::
[2024-07-22T12:13:42.364+0000] {subprocess.py:63} INFO - Tmp dir root location: /tmp
[2024-07-22T12:13:42.365+0000] {subprocess.py:75} INFO - Running command: ['/usr/bin/bash', '-c', 'docker exec -it dagcreation-spark-master-1  sh -c "spark-submit --master spark://spark:7077 /opt/airflow/spark/count_rows.py"']
[2024-07-22T12:13:42.373+0000] {subprocess.py:86} INFO - Output:
[2024-07-22T12:13:42.465+0000] {subprocess.py:93} INFO - Cannot connect to the Docker daemon at unix:///var/run/docker.sock. Is the docker daemon running?
[2024-07-22T12:13:42.466+0000] {subprocess.py:97} INFO - Command exited with return code 1
[2024-07-22T12:13:42.467+0000] {taskinstance.py:441} INFO - ::group::Post task execution logs
[2024-07-22T12:13:42.476+0000] {taskinstance.py:2905} ERROR - Task failed with exception
Traceback (most recent call last):
  File "/home/airflow/.local/lib/python3.12/site-packages/airflow/models/taskinstance.py", line 465, in _execute_task
    result = _execute_callable(context=context, **execute_callable_kwargs)
             ^^^^^^^^^^^^^^^^^^^^^^^^^^^^^^^^^^^^^^^^^^^^^^^^^^^^^^^^^^^^^
  File "/home/airflow/.local/lib/python3.12/site-packages/airflow/models/taskinstance.py", line 432, in _execute_callable
    return execute_callable(context=context, **execute_callable_kwargs)
           ^^^^^^^^^^^^^^^^^^^^^^^^^^^^^^^^^^^^^^^^^^^^^^^^^^^^^^^^^^^^
  File "/home/airflow/.local/lib/python3.12/site-packages/airflow/models/baseoperator.py", line 401, in wrapper
    return func(self, *args, **kwargs)
           ^^^^^^^^^^^^^^^^^^^^^^^^^^^
  File "/home/airflow/.local/lib/python3.12/site-packages/airflow/operators/bash.py", line 243, in execute
    raise AirflowException(
airflow.exceptions.AirflowException: Bash command failed. The command returned a non-zero exit code 1.
[2024-07-22T12:13:42.480+0000] {taskinstance.py:1206} INFO - Marking task as FAILED. dag_id=count_accidents, task_id=number_of_accidents, run_id=manual__2024-07-22T12:13:40.726568+00:00, execution_date=20240722T121340, start_date=20240722T121342, end_date=20240722T121342
[2024-07-22T12:13:42.488+0000] {standard_task_runner.py:110} ERROR - Failed to execute job 1785 for task number_of_accidents (Bash command failed. The command returned a non-zero exit code 1.; 525)
[2024-07-22T12:13:42.533+0000] {local_task_job_runner.py:240} INFO - Task exited with return code 1
[2024-07-22T12:13:42.548+0000] {taskinstance.py:3503} INFO - 0 downstream tasks scheduled from follow-on schedule check
[2024-07-22T12:13:42.549+0000] {local_task_job_runner.py:222} INFO - ::endgroup::
