[2024-07-19T11:51:45.584+0000] {local_task_job_runner.py:120} INFO - ::group::Pre task execution logs
[2024-07-19T11:51:45.601+0000] {taskinstance.py:2076} INFO - Dependencies all met for dep_context=non-requeueable deps ti=<TaskInstance: sql_dag.check_if_table_exists manual__2024-07-19T11:51:41.458342+00:00 [queued]>
[2024-07-19T11:51:45.605+0000] {taskinstance.py:2076} INFO - Dependencies all met for dep_context=requeueable deps ti=<TaskInstance: sql_dag.check_if_table_exists manual__2024-07-19T11:51:41.458342+00:00 [queued]>
[2024-07-19T11:51:45.605+0000] {taskinstance.py:2306} INFO - Starting attempt 1 of 1
[2024-07-19T11:51:45.611+0000] {taskinstance.py:2330} INFO - Executing <Task(BranchPythonOperator): check_if_table_exists> on 2024-07-19 11:51:41.458342+00:00
[2024-07-19T11:51:45.615+0000] {warnings.py:112} WARNING - /home/airflow/.local/lib/python3.12/site-packages/airflow/task/task_runner/standard_task_runner.py:61: DeprecationWarning: This process (pid=768) is multi-threaded, use of fork() may lead to deadlocks in the child.
  pid = os.fork()

[2024-07-19T11:51:45.615+0000] {standard_task_runner.py:63} INFO - Started process 770 to run task
[2024-07-19T11:51:45.616+0000] {standard_task_runner.py:90} INFO - Running: ['airflow', 'tasks', 'run', 'sql_dag', 'check_if_table_exists', 'manual__2024-07-19T11:51:41.458342+00:00', '--job-id', '1611', '--raw', '--subdir', 'DAGS_FOLDER/sql.py', '--cfg-path', '/tmp/tmp2_ha02nt']
[2024-07-19T11:51:45.617+0000] {standard_task_runner.py:91} INFO - Job 1611: Subtask check_if_table_exists
[2024-07-19T11:51:45.652+0000] {task_command.py:426} INFO - Running <TaskInstance: sql_dag.check_if_table_exists manual__2024-07-19T11:51:41.458342+00:00 [running]> on host b6c6b8dd133d
[2024-07-19T11:51:45.721+0000] {taskinstance.py:2648} INFO - Exporting env vars: AIRFLOW_CTX_DAG_OWNER='airflow' AIRFLOW_CTX_DAG_ID='sql_dag' AIRFLOW_CTX_TASK_ID='check_if_table_exists' AIRFLOW_CTX_EXECUTION_DATE='2024-07-19T11:51:41.458342+00:00' AIRFLOW_CTX_TRY_NUMBER='1' AIRFLOW_CTX_DAG_RUN_ID='manual__2024-07-19T11:51:41.458342+00:00'
[2024-07-19T11:51:45.722+0000] {taskinstance.py:430} INFO - ::endgroup::
[2024-07-19T11:51:45.723+0000] {baseoperator.py:400} WARNING - BranchPythonOperator.execute cannot be called outside TaskInstance!
[2024-07-19T11:51:45.732+0000] {base.py:84} INFO - Using connection ID 'postgres_default' for task execution.
[2024-07-19T11:51:45.733+0000] {taskinstance.py:441} INFO - ::group::Post task execution logs
[2024-07-19T11:51:45.733+0000] {taskinstance.py:2905} ERROR - Task failed with exception
Traceback (most recent call last):
  File "/home/airflow/.local/lib/python3.12/site-packages/airflow/models/taskinstance.py", line 465, in _execute_task
    result = _execute_callable(context=context, **execute_callable_kwargs)
             ^^^^^^^^^^^^^^^^^^^^^^^^^^^^^^^^^^^^^^^^^^^^^^^^^^^^^^^^^^^^^
  File "/home/airflow/.local/lib/python3.12/site-packages/airflow/models/taskinstance.py", line 432, in _execute_callable
    return execute_callable(context=context, **execute_callable_kwargs)
           ^^^^^^^^^^^^^^^^^^^^^^^^^^^^^^^^^^^^^^^^^^^^^^^^^^^^^^^^^^^^
  File "/home/airflow/.local/lib/python3.12/site-packages/airflow/models/baseoperator.py", line 401, in wrapper
    return func(self, *args, **kwargs)
           ^^^^^^^^^^^^^^^^^^^^^^^^^^^
  File "/home/airflow/.local/lib/python3.12/site-packages/airflow/operators/python.py", line 269, in execute
    return self.do_branch(context, super().execute(context))
                                   ^^^^^^^^^^^^^^^^^^^^^^^^
  File "/home/airflow/.local/lib/python3.12/site-packages/airflow/models/baseoperator.py", line 401, in wrapper
    return func(self, *args, **kwargs)
           ^^^^^^^^^^^^^^^^^^^^^^^^^^^
  File "/home/airflow/.local/lib/python3.12/site-packages/airflow/operators/python.py", line 235, in execute
    return_value = self.execute_callable()
                   ^^^^^^^^^^^^^^^^^^^^^^^
  File "/home/airflow/.local/lib/python3.12/site-packages/airflow/operators/python.py", line 252, in execute_callable
    return self.python_callable(*self.op_args, **self.op_kwargs)
           ^^^^^^^^^^^^^^^^^^^^^^^^^^^^^^^^^^^^^^^^^^^^^^^^^^^^^
  File "/opt/airflow/dags/sql.py", line 25, in check_table_exist
    query = hook.get_first(sql=sql_to_check_table_exist.format(table_name))
            ^^^^^^^^^^^^^^^^^^^^^^^^^^^^^^^^^^^^^^^^^^^^^^^^^^^^^^^^^^^^^^^
  File "/home/airflow/.local/lib/python3.12/site-packages/airflow/providers/common/sql/hooks/sql.py", line 312, in get_first
    return self.run(sql=sql, parameters=parameters, handler=fetch_one_handler)
           ^^^^^^^^^^^^^^^^^^^^^^^^^^^^^^^^^^^^^^^^^^^^^^^^^^^^^^^^^^^^^^^^^^^
  File "/home/airflow/.local/lib/python3.12/site-packages/airflow/providers/common/sql/hooks/sql.py", line 431, in run
    with self._create_autocommit_connection(autocommit) as conn:
  File "/usr/local/lib/python3.12/contextlib.py", line 137, in __enter__
    return next(self.gen)
           ^^^^^^^^^^^^^^
  File "/home/airflow/.local/lib/python3.12/site-packages/airflow/providers/common/sql/hooks/sql.py", line 551, in _create_autocommit_connection
    with closing(self.get_conn()) as conn:
                 ^^^^^^^^^^^^^^^
  File "/home/airflow/.local/lib/python3.12/site-packages/airflow/providers/postgres/hooks/postgres.py", line 175, in get_conn
    self.conn = psycopg2.connect(**conn_args)
                ^^^^^^^^^^^^^^^^^^^^^^^^^^^^^
  File "/home/airflow/.local/lib/python3.12/site-packages/psycopg2/__init__.py", line 122, in connect
    conn = _connect(dsn, connection_factory=connection_factory, **kwasync)
           ^^^^^^^^^^^^^^^^^^^^^^^^^^^^^^^^^^^^^^^^^^^^^^^^^^^^^^^^^^^^^^^
psycopg2.OperationalError: connection to server at "localhost" (::1), port 5432 failed: Connection refused
	Is the server running on that host and accepting TCP/IP connections?
connection to server at "localhost" (127.0.0.1), port 5432 failed: Connection refused
	Is the server running on that host and accepting TCP/IP connections?

[2024-07-19T11:51:45.742+0000] {taskinstance.py:1206} INFO - Marking task as FAILED. dag_id=sql_dag, task_id=check_if_table_exists, run_id=manual__2024-07-19T11:51:41.458342+00:00, execution_date=20240719T115141, start_date=20240719T115145, end_date=20240719T115145
[2024-07-19T11:51:45.751+0000] {standard_task_runner.py:110} ERROR - Failed to execute job 1611 for task check_if_table_exists (connection to server at "localhost" (::1), port 5432 failed: Connection refused
	Is the server running on that host and accepting TCP/IP connections?
connection to server at "localhost" (127.0.0.1), port 5432 failed: Connection refused
	Is the server running on that host and accepting TCP/IP connections?
; 770)
[2024-07-19T11:51:45.756+0000] {local_task_job_runner.py:240} INFO - Task exited with return code 1
[2024-07-19T11:51:45.778+0000] {taskinstance.py:3503} INFO - 0 downstream tasks scheduled from follow-on schedule check
[2024-07-19T11:51:45.781+0000] {local_task_job_runner.py:222} INFO - ::endgroup::
